Workbook

Sheet Dashboard
A1: Moya Trail Gear | 2026 Practice Financial Model
B4: Full-year revenue | E4: Full-year net income | H4: December cash | K4: December balance check
B5: =SUM('Income Statement'!B5:M5) -> 992022.12 | E5: =SUM('Income Statement'!B22:M22) -> 130577.2 | H5: ='Balance Sheet'!M5 -> 133923.03 | K5: ='Balance Sheet'!M23 -> 0
B7: Model at a glance
B8: Actual period | C8: Jan–Mar 2026
B9: Forecast period | C9: Apr–Dec 2026
B10: Revenue growth (Apr) | C10: =Assumptions!B4 -> 0.08
B11: COGS assumption | C11: =Assumptions!B7 -> 0.42
B12: Cash / credit sales mix | C12: =Assumptions!B5&" / "&Assumptions!B6 -> 0,6 / 0,4
B13: July equipment purchase | C13: =Assumptions!E14 -> 18000
B14: Monthly loan repayment | C14: =Assumptions!B18 -> 2000
B15: Check status | C15: =IF(COUNTIF(Checks!B14:M14,"REVIEW")=0,"PASS","REVIEW") -> PASS

Sheet Read Me
A1: This is how I use the model
A4: Purpose | B4: Model Moya Trail Gear monthly from Jan to Dec 2026; three actual months and nine forecast months.
A5: Workbook flow | B5: Raw Journal → Clean Journal / OpeningTB → Income Statement and schedules → Cash Flow and Balance Sheet → Dashboard and Checks.
A6: 1. Review source data | B6: Raw Journal is retained as provided. Clean Journal contains the standardized entries used by the model. OpeningTB provides balances at 31 Dec 2025.
A7: 2. Change assumptions | B7: Edit blue font cells with yellow fill on Assumptions for monthly growth, mix, COGS, stock, operating costs, capex, depreciation, debt, interest, and tax.
A8: 3. Read the statements | B8: Income Statement shows monthly actuals and forecast. Cash Flow uses the indirect method. Balance Sheet includes monthly balance check.
A9: 4. Inspect schedules | B9: Working Capital explains sales collection, receivables, stock, purchases, and supplier payments. PP&E & Debt explains depreciation, principal, and interest.
A10: 5. Review checks | B10: Checks should be zero and Overall Status should show PASS. Review any non-zero difference.
A11: Input conventions | B11: Blue font and pale yellow fill are editable inputs. Black font indicates formulas. Jan–Mar actual; Apr–Dec forecast.
A12: Important interpretation | B12: Training model using fictional data, not an audited forecast. Negative cash remains visible as a funding shortfall.
A13: Simplifications | B13: No VAT, seasonality, new borrowing, dividends, equity changes, inventory losses, bad debts, asset disposals, or tax timing differences. Dec inventory uses Dec COGS as terminal proxy.
A14: Data quality note | B14: Raw Journal contains inconsistent source date/account formats. Clean Journal is the model input and normalizes those entries; verify the mapping before reusing with live data.

Sheet Raw Journal
A1: Source line ID | B1: Journal reference (raw) | C1: Date (raw) | D1: Narrative (raw) | E1: Account name (raw) | F1: Debit (raw) | G1: Credit (raw) | H1: Counterparty (raw) | I1: Source file (raw)
A2: L001 | B2: SALE-Jan-A | C2: 2026-01-03 | D2: Jan online orders - card settlement | E2: Capitec Current | F2: R35,000.00 | H2: Web customers | I2: ERP-Journal-Q1
A3: L002 | B3: SALE-Jan-A | C3: 2026-01-03 | D3: Jan online orders - card settlement | E3: Accounts Receivable | F3: 19 000.00 | H3: Web customers | I3: ERP-Journal-Q1
A4: L003 | B4: SALE-Jan-A | C4: 2026-01-03 | D4: Jan online orders - card settlement | E4: Sales | G4: 54,000 | H4: Web customers | I4: ERP-Journal-Q1
A5: L004 | B5: COLL-Jan | C5: 05/01/2026 | D5: Collection of prior customer invoices | E5: Bank | F5: R 10 000.00 | H5: Customers | I5: ERP-Journal-Q1
A6: L005 | B6: COLL-Jan | C6: 05/01/2026 | D6: Collection of prior customer invoices | E6: Customer receivable | G6: R10,000.00 | H6: Customers | I6: ERP-Journal-Q1
A7: L006 | B7: COGS-Jan | C7: 2026/01/08 | D7: Product cost for sales | E7: Product cost | F7: 22 680.00 | H7: Inventory | I7: ERP-Journal-Q1
A8: L007 | B8: COGS-Jan | C8: 2026/01/08 | D8: Product cost for sales | E8: Inventory | G8: 22,680 | H8: Inventory | I8: ERP-Journal-Q1
A9: L008 | B9: PUR-Jan | C9: 12 Jan 2026 | D9: Supplier invoice - inventory | E9: Inventory | F9: R 25 000.00 | H9: Cape Trail Supplies | I9: ERP-Journal-Q1
A10: L009 | B10: PUR-Jan | C10: 12 Jan 2026 | D10: SUPPLIER INVOICE - INVENTORY | E10: Accounts Payable | G10: R25,000.00 | H10: Cape Trail Supplies | I10: ERP-Journal-Q1
A11: L010 | B11: PAY-SUP-Jan | C11: 42030 | D11: Payment to inventory supplier | E11: Accounts Payable | F11: 17 000.00 | H11: Cape Trail Supplies | I11: ERP-Journal-Q1
A12: L011 | B12: PAY-SUP-Jan | C12: 15-01-26 | D12: Payment to inventory supplier | E12: Bank | G12: 17,000 | H12: Cape Trail Supplies | I12: ERP-Journal-Q1
A13: L012 | B13: PAYROLL-Jan | C13: 01/21/2026 | D13: Monthly payroll | E13: Payroll expense | F13: R 15 500.00 | H13: Staff | I13: ERP-Journal-Q1
A14: L013 | B14: PAYROLL-Jan | C14: 01/21/2026 | D14: Monthly payroll | E14: Business Account | G14: R15,500.00 | I14: ERP-Journal-Q1
A15: L014 | B15: RENT-Jan | C15: 2026-01-25 | D15: Warehouse rent | E15: Warehouse Rent | F15: 9 000.00 | H15: Moya Property Holdings | I15: ERP-Journal-Q1
A16: L015 | B16: RENT-Jan | C16: 2026-01-25 | D16: Warehouse rent | E16: Capitec bank | G16: 9,000 | H16: Moya Property Holdings | I16: ERP-Journal-Q1
A17: L016 | B17: MKT-Jan | C17: Jan 28, 2026 | D17: Online marketing spend | E17: Marketing | F17: R 3 500.00 | H17: Digital Reach | I17: ERP-Journal-Q1
A18: L017 | B18: MKT-Jan | C18: Jan 28, 2026 | D18: Online marketing spend | E18: Capitec Current | G18: R3,500.00 | H18: Digital Reach | I18: ERP-Journal-Q1
A19: L018 | B19: UTIL-Jan | C19: 2026-01-03 | D19: ELECTRICITY AND WATER | E19: Power and water | F19: 1 200.00 | H19: Municipal account | I19: ERP-Journal-Q1
A20: L019 | B20: UTIL-Jan | C20: 2026-01-03 | D20: Electricity and water | E20: Bank | G20: 1,200 | H20: Municipal account | I20: ERP-Journal-Q1
A21: L020 | B21: CAPEX-Jan | C21: 05/01/2026 | D21: Packing and dispatch equipment purchase | E21: Equipment | F21: R 12 000.00 | H21: PackPro | I21: ERP-Journal-Q1
A22: L021 | B22: CAPEX-Jan | C22: 05/01/2026 | D22: Packing and dispatch equipment purchase | E22: Business Account | G22: R12,000.00 | H22: PackPro | I22: ERP-Journal-Q1
A23: L022 | B23: DEP-Jan | C23: 2026/01/08 | D23: Monthly depreciation charge | E23: Depn | F23: 1 333.33 | H23: Month-end journal | I23: ERP-Journal-Q1
A24: L023 | B24: DEP-Jan | C24: 2026/01/08 | D24: Monthly depreciation charge | E24: Accum depn | G24: 1,333 | H24: Month-end journal | I24: ERP-Journal-Q1
A25: L024 | B25: INT-Jan | C25: 12 Jan 2026 | D25: Loan interest charge and payment | E25: Interest | F25: R 350.00 | H25: Bank | I25: ERP-Journal-Q1
A26: L025 | B26: INT-Jan | C26: 12 Jan 2026 | D26: Loan interest charge and payment | E26: Capitec Current | G26: R350.00 | H26: Bank | I26: ERP-Journal-Q1
A27: L026 | B27: LOAN-Jan | C27: 15-01-26 | D27: Monthly loan principal payment | E27: Business Loan | F27: 2 000.00 | I27: ERP-Journal-Q1
A28: L027 | B28: LOAN-Jan | C28: 15-01-26 | D28: MONTHLY LOAN PRINCIPAL PAYMENT | E28: Bank | G28: 2,000 | H28: Bank | I28: ERP-Journal-Q1
A29: L028 | B29: TAX-Jan | C29: 01/21/2026 | D29: Income tax provision and payment | E29: Tax | F29: R 117.90 | H29: Tax authority | I29: ERP-Journal-Q1
A30: L029 | B30: TAX-Jan | C30: 01/21/2026 | D30: Income tax provision and payment | E30: Business Account | G30: R117.90 | H30: Tax authority | I30: ERP-Journal-Q1
A31: L030 | B31: SALE-Feb-A | C31: 2026-02-03 | D31: Feb online orders - card settlement | E31: Bank | F31: R39,000.00 | H31: Web customers | I31: ERP-Journal-Q1
A32: L031 | B32: SALE-Feb-A | C32: 2026-02-03 | D32: Feb online orders - card settlement | E32: Customer receivable | F32: 20 000.00 | H32: Web customers | I32: ERP-Journal-Q1
A33: L032 | B33: SALE-Feb-A | C33: 2026-02-03 | D33: Feb online orders - card settlement | E33: Online Sales | G33: 59,000 | H33: Web customers | I33: ERP-Journal-Q1
A34: L033 | B34: COLL-Feb | C34: 05/02/2026 | D34: Collection of prior customer invoices | E34: Business Account | F34: R 19 000.00 | H34: Customers | I34: ERP-Journal-Q1
A35: L034 | B35: COLL-Feb | C35: 05/02/2026 | D35: Collection of prior customer invoices | E35: Trade Debtors | G35: R19,000.00 | H35: Customers | I35: ERP-Journal-Q1
A36: L035 | B36: COGS-Feb | C36: 2026/02/08 | D36: Product cost for sales | E36: Cost of Sales | F36: 24 780.00 | H36: Inventory | I36: ERP-Journal-Q1
A37: L036 | B37: COGS-Feb | C37: 2026/02/08 | D37: PRODUCT COST FOR SALES | E37: Stock | G37: 24,780 | H37: Inventory | I37: ERP-Journal-Q1
A38: L037 | B38: PUR-Feb | C38: 12 Feb 2026 | D38: Supplier invoice - inventory | E38: Stock | F38: R 28 000.00 | H38: Cape Trail Supplies | I38: ERP-Journal-Q1
A39: L038 | B39: PUR-Feb | C39: 12 Feb 2026 | D39: Supplier invoice - inventory | E39: Suppliers Control | G39: R28,000.00 | H39: Cape Trail Supplies | I39: ERP-Journal-Q1
A40: L039 | B40: PAY-SUP-Feb | C40: 15-02-26 | D40: Payment to inventory supplier | E40: Suppliers Control | F40: 25 000.00 | I40: ERP-Journal-Q1
...

Sheet OpeningTB
A1: As of date | B1: Account name | C1: Debit balance | D1: Credit balance | E1: Source note
A2: 31-Dec-2025 | B2: Bank | C2: 68000 | E2: Opening cash balance
A3: 31-Dec-2025 | B3: Accounts Receivable | C3: 12000 | E3: Customer balances due
A4: 31-Dec-2025 | B4: Inventory | C4: 42000 | E4: Inventory on hand
A5: 31-Dec-2025 | B5: Equipment | C5: 36000 | E5: Gross equipment cost
A6: 31-Dec-2025 | B6: Accumulated Depreciation | D6: 9000 | E6: Accumulated depreciation
A7: 31-Dec-2025 | B7: Accounts Payable | D7: 17000 | E7: Supplier balances due
A8: 31-Dec-2025 | B8: Business Loan | D8: 28000 | E8: Loan balance
A9: 31-Dec-2025 | B9: Owner Capital | D9: 70000 | E9: Share capital
A10: 31-Dec-2025 | B10: Retained Earnings | D10: 34000 | E10: Retained earnings

Sheet Clean Journal
A1: Source line ID | B1: Journal reference | C1: Date | D1: Narrative | E1: Account name | F1: Debit | G1: Credit | H1: Counterparty | I1: Source file
A2: L001 | B2: SALE-Jan-A | C2: 46025 | D2: Jan online orders - card settlement | E2: Bank | F2: 35000 | H2: Web customers | I2: ERP-Journal-Q1
A3: L002 | B3: SALE-Jan-A | C3: 46025 | D3: Jan online orders - card settlement | E3: Accounts Receivable | F3: 19000 | H3: Web customers | I3: ERP-Journal-Q1
A4: L003 | B4: SALE-Jan-A | C4: 46025 | D4: Jan online orders - card settlement | E4: Sales Revenue | G4: 54000 | H4: Web customers | I4: ERP-Journal-Q1
A5: L004 | B5: COLL-Jan | C5: 46027 | D5: Collection of prior customer invoices | E5: Bank | F5: 10000 | H5: Customers | I5: ERP-Journal-Q1
A6: L005 | B6: COLL-Jan | C6: 46027 | D6: Collection of prior customer invoices | E6: Accounts Receivable | G6: 10000 | H6: Customers | I6: ERP-Journal-Q1
A7: L006 | B7: COGS-Jan | C7: 46030 | D7: Product cost for sales | E7: Cost of Sales | F7: 22680 | H7: Inventory | I7: ERP-Journal-Q1
A8: L007 | B8: COGS-Jan | C8: 46030 | D8: Product cost for sales | E8: Inventory | G8: 22680 | H8: Inventory | I8: ERP-Journal-Q1
A9: L008 | B9: PUR-Jan | C9: 46034 | D9: Supplier invoice - inventory | E9: Inventory | F9: 25000 | H9: Cape Trail Supplies | I9: ERP-Journal-Q1
A10: L009 | B10: PUR-Jan | C10: 46034 | D10: SUPPLIER INVOICE - INVENTORY | E10: Accounts Payable | G10: 25000 | H10: Cape Trail Supplies | I10: ERP-Journal-Q1
A11: L010 | B11: PAY-SUP-Jan | C11: 46037 | D11: Payment to inventory supplier | E11: Accounts Payable | F11: 17000 | H11: Cape Trail Supplies | I11: ERP-Journal-Q1
A12: L011 | B12: PAY-SUP-Jan | C12: 46037 | D12: Payment to inventory supplier | E12: Bank | G12: 17000 | H12: Cape Trail Supplies | I12: ERP-Journal-Q1
A13: L012 | B13: PAYROLL-Jan | C13: 46043 | D13: Monthly payroll | E13: Payroll Expense | F13: 15500 | H13: Staff | I13: ERP-Journal-Q1
A14: L013 | B14: PAYROLL-Jan | C14: 46043 | D14: Monthly payroll | E14: Bank | G14: 15500 | I14: ERP-Journal-Q1
A15: L014 | B15: RENT-Jan | C15: 46047 | D15: Warehouse rent | E15: Rent Expense | F15: 9000 | H15: Moya Property Holdings | I15: ERP-Journal-Q1
A16: L015 | B16: RENT-Jan | C16: 46047 | D16: Warehouse rent | E16: Bank | G16: 9000 | H16: Moya Property Holdings | I16: ERP-Journal-Q1
A17: L016 | B17: MKT-Jan | C17: 46050 | D17: Online marketing spend | E17: Marketing Expense | F17: 3500 | H17: Digital Reach | I17: ERP-Journal-Q1
A18: L017 | B18: MKT-Jan | C18: 46050 | D18: Online marketing spend | E18: Bank | G18: 3500 | H18: Digital Reach | I18: ERP-Journal-Q1
A19: L018 | B19: UTIL-Jan | C19: 46025 | D19: ELECTRICITY AND WATER | E19: Utilities Expense | F19: 1200 | H19: Municipal account | I19: ERP-Journal-Q1
A20: L019 | B20: UTIL-Jan | C20: 46025 | D20: Electricity and water | E20: Bank | G20: 1200 | H20: Municipal account | I20: ERP-Journal-Q1
A21: L020 | B21: CAPEX-Jan | C21: 46027 | D21: Packing and dispatch equipment purchase | E21: Equipment | F21: 12000 | H21: PackPro | I21: ERP-Journal-Q1
A22: L021 | B22: CAPEX-Jan | C22: 46027 | D22: Packing and dispatch equipment purchase | E22: Bank | G22: 12000 | H22: PackPro | I22: ERP-Journal-Q1
A23: L022 | B23: DEP-Jan | C23: 46030 | D23: Monthly depreciation charge | E23: Depreciation Expense | F23: 1333.33 | H23: Month-end journal | I23: ERP-Journal-Q1
A24: L023 | B24: DEP-Jan | C24: 46030 | D24: Monthly depreciation charge | E24: Accumulated Depreciation | G24: 1333.33 | H24: Month-end journal | I24: ERP-Journal-Q1
A25: L024 | B25: INT-Jan | C25: 46034 | D25: Loan interest charge and payment | E25: Interest Expense | F25: 350 | H25: Bank | I25: ERP-Journal-Q1
A26: L025 | B26: INT-Jan | C26: 46034 | D26: Loan interest charge and payment | E26: Bank | G26: 350 | H26: Bank | I26: ERP-Journal-Q1
A27: L026 | B27: LOAN-Jan | C27: 46037 | D27: Monthly loan principal payment | E27: Business Loan | F27: 2000 | I27: ERP-Journal-Q1
A28: L027 | B28: LOAN-Jan | C28: 46037 | D28: MONTHLY LOAN PRINCIPAL PAYMENT | E28: Bank | G28: 2000 | H28: Bank | I28: ERP-Journal-Q1
A29: L028 | B29: TAX-Jan | C29: 46043 | D29: Income tax provision and payment | E29: Income Tax Expense | F29: 117.9 | H29: Tax authority | I29: ERP-Journal-Q1
A30: L029 | B30: TAX-Jan | C30: 46043 | D30: Income tax provision and payment | E30: Bank | G30: 117.9 | H30: Tax authority | I30: ERP-Journal-Q1
A31: L030 | B31: SALE-Feb-A | C31: 46056 | D31: Feb online orders - card settlement | E31: Bank | F31: 39000 | H31: Web customers | I31: ERP-Journal-Q1
A32: L031 | B32: SALE-Feb-A | C32: 46056 | D32: Feb online orders - card settlement | E32: Accounts Receivable | F32: 20000 | H32: Web customers | I32: ERP-Journal-Q1
A33: L032 | B33: SALE-Feb-A | C33: 46056 | D33: Feb online orders - card settlement | E33: Sales Revenue | G33: 59000 | H33: Web customers | I33: ERP-Journal-Q1
A34: L033 | B34: COLL-Feb | C34: 46058 | D34: Collection of prior customer invoices | E34: Bank | F34: 19000 | H34: Customers | I34: ERP-Journal-Q1
A35: L034 | B35: COLL-Feb | C35: 46058 | D35: Collection of prior customer invoices | E35: Accounts Receivable | G35: 19000 | H35: Customers | I35: ERP-Journal-Q1
A36: L035 | B36: COGS-Feb | C36: 46061 | D36: Product cost for sales | E36: Cost of Sales | F36: 24780 | H36: Inventory | I36: ERP-Journal-Q1
A37: L036 | B37: COGS-Feb | C37: 46061 | D37: PRODUCT COST FOR SALES | E37: Inventory | G37: 24780 | H37: Inventory | I37: ERP-Journal-Q1
A38: L037 | B38: PUR-Feb | C38: 46065 | D38: Supplier invoice - inventory | E38: Inventory | F38: 28000 | H38: Cape Trail Supplies | I38: ERP-Journal-Q1
A39: L038 | B39: PUR-Feb | C39: 46065 | D39: Supplier invoice - inventory | E39: Accounts Payable | G39: 28000 | H39: Cape Trail Supplies | I39: ERP-Journal-Q1
A40: L039 | B40: PAY-SUP-Feb | C40: 46068 | D40: Payment to inventory supplier | E40: Accounts Payable | F40: 25000 | I40: ERP-Journal-Q1
...

Sheet Assumptions
A1: Moya Trail Gear | Forecast Assumptions
A3: Forecast driver | B3: 46113 | C3: 46143 | D3: 46174 | E3: 46204 | F3: 46235 | G3: 46266 | H3: 46296 | I3: 46327 | J3: 46357
A4: Revenue growth | B4: 0.08 | C4: 0.08 | D4: 0.08 | E4: 0.05 | F4: 0.05 | G4: 0.05 | H4: 0.03 | I4: 0.03 | J4: 0.03
A5: Cash sales mix | B5: 0.6 | C5: 0.6 | D5: 0.6 | E5: 0.6 | F5: 0.6 | G5: 0.6 | H5: 0.6 | I5: 0.6 | J5: 0.6
A6: Credit sales mix | B6: 0.4 | C6: 0.4 | D6: 0.4 | E6: 0.4 | F6: 0.4 | G6: 0.4 | H6: 0.4 | I6: 0.4 | J6: 0.4
A7: COGS as % of revenue | B7: 0.42 | C7: 0.42 | D7: 0.42 | E7: 0.42 | F7: 0.42 | G7: 0.42 | H7: 0.42 | I7: 0.42 | J7: 0.42
A8: Inventory cover (months) | B8: 1.5 | C8: 1.5 | D8: 1.5 | E8: 1.5 | F8: 1.5 | G8: 1.5 | H8: 1.5 | I8: 1.5 | J8: 1.5
A9: Supplier payment delay (months) | B9: 1 | C9: 1 | D9: 1 | E9: 1 | F9: 1 | G9: 1 | H9: 1 | I9: 1 | J9: 1
A10: Monthly salaries | B10: 15500 | C10: 15500 | D10: 15500 | E10: 16275 | F10: 16275 | G10: 16275 | H10: 16275 | I10: 16275 | J10: 16275
A11: Monthly rent | B11: 9000 | C11: 9000 | D11: 9000 | E11: 9000 | F11: 9000 | G11: 9000 | H11: 9000 | I11: 9000 | J11: 9000
A12: Monthly marketing | B12: 5000 | C12: 5000 | D12: 5000 | E12: 6000 | F12: 6000 | G12: 6000 | H12: 6000 | I12: 6000 | J12: 6000
A13: Monthly utilities | B13: 1300 | C13: 1300 | D13: 1300 | E13: 1300 | F13: 1300 | G13: 1300 | H13: 1300 | I13: 1300 | J13: 1300
A14: Equipment purchase | E14: 18000
A15: Equipment useful life (months) | E15: 36
A16: Existing monthly depreciation | B16: 1333.33 | C16: 1333.33 | D16: 1333.33 | E16: 1333.33 | F16: 1333.33 | G16: 1333.33 | H16: 1333.33 | I16: 1333.33 | J16: 1333.33
A17: Annual interest rate | B17: 0.15 | C17: 0.15 | D17: 0.15 | E17: 0.15 | F17: 0.15 | G17: 0.15 | H17: 0.15 | I17: 0.15 | J17: 0.15
A18: Monthly loan principal repayment | B18: 2000 | C18: 2000 | D18: 2000 | E18: 2000 | F18: 2000 | G18: 2000 | H18: 2000 | I18: 2000 | J18: 2000
A19: Tax rate | B19: 0.27 | C19: 0.27 | D19: 0.27 | E19: 0.27 | F19: 0.27 | G19: 0.27 | H19: 0.27 | I19: 0.27 | J19: 0.27
A22: Model conventions
A23: • Actuals: Jan–Mar 2026. Forecast: Apr–Dec 2026.
A24: • Cash sales are collected in month of sale; credit sales are collected one month later. March receivables are collected in April.
A25: • Inventory purchases = COGS + ending inventory − opening inventory. Purchases are paid one month later.
A26: • Taxes are paid in the month accrued. No dividends, new borrowing, equity contributions, or revolver are assumed.
A27: • Negative cash remains visible as a funding warning. No VAT, seasonality, bad debts, stock losses, disposals, or deferred tax are modeled.
A28: • December inventory cover uses December COGS as the terminal proxy. All amounts are fictional South African rand.

Sheet Income Statement
A1: Integrated Income Statement
B3: 46023 | C3: 46054 | D3: 46082 | E3: 46113 | F3: 46143 | G3: 46174 | H3: 46204 | I3: 46235 | J3: 46266 | K3: 46296 | L3: 46327 | M3: 46357
A4: Period type | B4: Actual | C4: Actual | D4: Actual | E4: Forecast | F4: Forecast | G4: Forecast | H4: Forecast | I4: Forecast | J4: Forecast | K4: Forecast | L4: Forecast | M4: Forecast
A5: Revenue | B5: =SUMIFS('Clean Journal'!$G:$G,'Clean Journal'!$E:$E,"Sales Revenue",'Clean Journal'!$C:$C,">="&B$3,'Clean Journal'!$C:$C,"<"&EDATE(B$3,1)) -> 54000 | C5: =SUMIFS('Clean Journal'!$G:$G,'Clean Journal'!$E:$E,"Sales Revenue",'Clean Journal'!$C:$C,">="&C$3,'Clean Journal'!$C:$C,"<"&EDATE(C$3,1)) -> 59000 | D5: =SUMIFS('Clean Journal'!$G:$G,'Clean Journal'!$E:$E,"Sales Revenue",'Clean Journal'!$C:$C,">="&D$3,'Clean Journal'!$C:$C,"<"&EDATE(D$3,1)) -> 66000 | E5: =D5*(1+Assumptions!B4) -> 71280 | F5: =E5*(1+Assumptions!C4) -> 76982.4 | G5: =F5*(1+Assumptions!D4) -> 83140.992 | H5: =G5*(1+Assumptions!E4) -> 87298.042 | I5: =H5*(1+Assumptions!F4) -> 91662.944 | J5: =I5*(1+Assumptions!G4) -> 96246.091 | K5: =J5*(1+Assumptions!H4) -> 99133.474 | L5: =K5*(1+Assumptions!I4) -> 102107.48 | M5: =L5*(1+Assumptions!J4) -> 105170.7
A6: Cost of sales | B6: =SUMIFS('Clean Journal'!$F:$F,'Clean Journal'!$E:$E,"Cost of Sales",'Clean Journal'!$C:$C,">="&B$3,'Clean Journal'!$C:$C,"<"&EDATE(B$3,1)) -> 22680 | C6: =SUMIFS('Clean Journal'!$F:$F,'Clean Journal'!$E:$E,"Cost of Sales",'Clean Journal'!$C:$C,">="&C$3,'Clean Journal'!$C:$C,"<"&EDATE(C$3,1)) -> 24780 | D6: =SUMIFS('Clean Journal'!$F:$F,'Clean Journal'!$E:$E,"Cost of Sales",'Clean Journal'!$C:$C,">="&D$3,'Clean Journal'!$C:$C,"<"&EDATE(D$3,1)) -> 27720 | E6: =E5*Assumptions!B7 -> 29937.6 | F6: =F5*Assumptions!C7 -> 32332.608 | G6: =G5*Assumptions!D7 -> 34919.217 | H6: =H5*Assumptions!E7 -> 36665.177 | I6: =I5*Assumptions!F7 -> 38498.436 | J6: =J5*Assumptions!G7 -> 40423.358 | K6: =K5*Assumptions!H7 -> 41636.059 | L6: =L5*Assumptions!I7 -> 42885.141 | M6: =M5*Assumptions!J7 -> 44171.695
A7: Gross profit | B7: =B5-B6 -> 31320 | C7: =C5-C6 -> 34220 | D7: =D5-D6 -> 38280 | E7: =E5-E6 -> 41342.4 | F7: =F5-F6 -> 44649.792 | G7: =G5-G6 -> 48221.775 | H7: =H5-H6 -> 50632.864 | I7: =I5-I6 -> 53164.507 | ... M7: =M5-M6 -> 60999.007
A8: Gross margin | B8: =IFERROR(B7/B5,0) -> 0.58 | C8: =IFERROR(C7/C5,0) -> 0.58 | D8: =IFERROR(D7/D5,0) -> 0.58 | E8: =IFERROR(E7/E5,0) -> 0.58 | F8: =IFERROR(F7/F5,0) -> 0.58 | G8: =IFERROR(G7/G5,0) -> 0.58 | H8: =IFERROR(H7/H5,0) -> 0.58 | I8: =IFERROR(I7/I5,0) -> 0.58 | ... M8: =IFERROR(M7/M5,0) -> 0.58
A10: Payroll expense | B10: =SUMIFS('Clean Journal'!$F:$F,'Clean Journal'!$E:$E,"Payroll Expense",'Clean Journal'!$C:$C,">="&B$3,'Clean Journal'!$C:$C,"<"&EDATE(B$3,1)) -> 15500 | C10: =SUMIFS('Clean Journal'!$F:$F,'Clean Journal'!$E:$E,"Payroll Expense",'Clean Journal'!$C:$C,">="&C$3,'Clean Journal'!$C:$C,"<"&EDATE(C$3,1)) -> 15500 | D10: =SUMIFS('Clean Journal'!$F:$F,'Clean Journal'!$E:$E,"Payroll Expense",'Clean Journal'!$C:$C,">="&D$3,'Clean Journal'!$C:$C,"<"&EDATE(D$3,1)) -> 15500 | E10: =Assumptions!B10 -> 15500 | F10: =Assumptions!C10 -> 15500 | G10: =Assumptions!D10 -> 15500 | H10: =Assumptions!E10 -> 16275 | I10: =Assumptions!F10 -> 16275 | J10: =Assumptions!G10 -> 16275 | K10: =Assumptions!H10 -> 16275 | L10: =Assumptions!I10 -> 16275 | M10: =Assumptions!J10 -> 16275
A11: Rent expense | B11: =SUMIFS('Clean Journal'!$F:$F,'Clean Journal'!$E:$E,"Rent Expense",'Clean Journal'!$C:$C,">="&B$3,'Clean Journal'!$C:$C,"<"&EDATE(B$3,1)) -> 9000 | C11: =SUMIFS('Clean Journal'!$F:$F,'Clean Journal'!$E:$E,"Rent Expense",'Clean Journal'!$C:$C,">="&C$3,'Clean Journal'!$C:$C,"<"&EDATE(C$3,1)) -> 9000 | D11: =SUMIFS('Clean Journal'!$F:$F,'Clean Journal'!$E:$E,"Rent Expense",'Clean Journal'!$C:$C,">="&D$3,'Clean Journal'!$C:$C,"<"&EDATE(D$3,1)) -> 9000 | E11: =Assumptions!B11 -> 9000 | F11: =Assumptions!C11 -> 9000 | G11: =Assumptions!D11 -> 9000 | H11: =Assumptions!E11 -> 9000 | I11: =Assumptions!F11 -> 9000 | J11: =Assumptions!G11 -> 9000 | K11: =Assumptions!H11 -> 9000 | L11: =Assumptions!I11 -> 9000 | M11: =Assumptions!J11 -> 9000
A12: Marketing expense | B12: =SUMIFS('Clean Journal'!$F:$F,'Clean Journal'!$E:$E,"Marketing Expense",'Clean Journal'!$C:$C,">="&B$3,'Clean Journal'!$C:$C,"<"&EDATE(B$3,1)) -> 3500 | C12: =SUMIFS('Clean Journal'!$F:$F,'Clean Journal'!$E:$E,"Marketing Expense",'Clean Journal'!$C:$C,">="&C$3,'Clean Journal'!$C:$C,"<"&EDATE(C$3,1)) -> 4000 | D12: =SUMIFS('Clean Journal'!$F:$F,'Clean Journal'!$E:$E,"Marketing Expense",'Clean Journal'!$C:$C,">="&D$3,'Clean Journal'!$C:$C,"<"&EDATE(D$3,1)) -> 5000 | E12: =Assumptions!B12 -> 5000 | F12: =Assumptions!C12 -> 5000 | G12: =Assumptions!D12 -> 5000 | H12: =Assumptions!E12 -> 6000 | I12: =Assumptions!F12 -> 6000 | J12: =Assumptions!G12 -> 6000 | K12: =Assumptions!H12 -> 6000 | L12: =Assumptions!I12 -> 6000 | M12: =Assumptions!J12 -> 6000
A13: Utilities expense | B13: =SUMIFS('Clean Journal'!$F:$F,'Clean Journal'!$E:$E,"Utilities Expense",'Clean Journal'!$C:$C,">="&B$3,'Clean Journal'!$C:$C,"<"&EDATE(B$3,1)) -> 1200 | C13: =SUMIFS('Clean Journal'!$F:$F,'Clean Journal'!$E:$E,"Utilities Expense",'Clean Journal'!$C:$C,">="&C$3,'Clean Journal'!$C:$C,"<"&EDATE(C$3,1)) -> 1200 | D13: =SUMIFS('Clean Journal'!$F:$F,'Clean Journal'!$E:$E,"Utilities Expense",'Clean Journal'!$C:$C,">="&D$3,'Clean Journal'!$C:$C,"<"&EDATE(D$3,1)) -> 1200 | E13: =Assumptions!B13 -> 1300 | F13: =Assumptions!C13 -> 1300 | G13: =Assumptions!D13 -> 1300 | H13: =Assumptions!E13 -> 1300 | I13: =Assumptions!F13 -> 1300 | J13: =Assumptions!G13 -> 1300 | K13: =Assumptions!H13 -> 1300 | L13: =Assumptions!I13 -> 1300 | M13: =Assumptions!J13 -> 1300
A14: Depreciation expense | B14: =SUMIFS('Clean Journal'!$F:$F,'Clean Journal'!$E:$E,"Depreciation Expense",'Clean Journal'!$C:$C,">="&B$3,'Clean Journal'!$C:$C,"<"&EDATE(B$3,1)) -> 1333.33 | C14: =SUMIFS('Clean Journal'!$F:$F,'Clean Journal'!$E:$E,"Depreciation Expense",'Clean Journal'!$C:$C,">="&C$3,'Clean Journal'!$C:$C,"<"&EDATE(C$3,1)) -> 1333.33 | D14: =SUMIFS('Clean Journal'!$F:$F,'Clean Journal'!$E:$E,"Depreciation Expense",'Clean Journal'!$C:$C,">="&D$3,'Clean Journal'!$C:$C,"<"&EDATE(D$3,1)) -> 1333.33 | E14: ='PP&E & Debt'!E9 -> 1333.33 | F14: ='PP&E & Debt'!F9 -> 1333.33 | G14: ='PP&E & Debt'!G9 -> 1333.33 | H14: ='PP&E & Debt'!H9 -> 1833.33 | I14: ='PP&E & Debt'!I9 -> 1333.33 | J14: ='PP&E & Debt'!J9 -> 1333.33 | K14: ='PP&E & Debt'!K9 -> 1333.33 | L14: ='PP&E & Debt'!L9 -> 1333.33 | M14: ='PP&E & Debt'!M9 -> 1333.33
A15: Total operating expenses | B15: =SUM(B10:B14) -> 30533.33 | C15: =SUM(C10:C14) -> 31033.33 | D15: =SUM(D10:D14) -> 32033.33 | E15: =SUM(E10:E14) -> 32133.33 | F15: =SUM(F10:F14) -> 32133.33 | G15: =SUM(G10:G14) -> 32133.33 | H15: =SUM(H10:H14) -> 34408.33 | I15: =SUM(I10:I14) -> 33908.33 | ... M15: =SUM(M10:M14) -> 33908.33
A16: EBITDA | B16: =B7-SUM(B10:B13) -> 2120 | C16: =C7-SUM(C10:C13) -> 4520 | D16: =D7-SUM(D10:D13) -> 7580 | E16: =E7-SUM(E10:E13) -> 10542.4 | F16: =F7-SUM(F10:F13) -> 13849.792 | G16: =G7-SUM(G10:G13) -> 17421.775 | H16: =H7-SUM(H10:H13) -> 18057.864 | I16: =I7-SUM(I10:I13) -> 20589.507 | ... M16: =M7-SUM(M10:M13) -> 28424.007
A17: EBITDA margin | B17: =IFERROR(B16/B5,0) -> 0.039259259 | C17: =IFERROR(C16/C5,0) -> 0.076610169 | D17: =IFERROR(D16/D5,0) -> 0.11484848 | E17: =IFERROR(E16/E5,0) -> 0.14790123 | F17: =IFERROR(F16/F5,0) -> 0.17990855 | G17: =IFERROR(G16/G5,0) -> 0.20954495 | H17: =IFERROR(H16/H5,0) -> 0.20685303 | I17: =IFERROR(I16/I5,0) -> 0.22462193 | ... M17: =IFERROR(M16/M5,0) -> 0.27026545
A18: Operating profit (EBIT) | B18: =B7-B15 -> 786.67 | C18: =C7-C15 -> 3186.67 | D18: =D7-D15 -> 6246.67 | E18: =E7-E15 -> 9209.07 | F18: =F7-F15 -> 12516.462 | G18: =G7-G15 -> 16088.445 | H18: =H7-H15 -> 16224.534 | I18: =I7-I15 -> 19256.177 | ... M18: =M7-M15 -> 27090.677
A19: Interest expense | B19: =SUMIFS('Clean Journal'!$F:$F,'Clean Journal'!$E:$E,"Interest Expense",'Clean Journal'!$C:$C,">="&B$3,'Clean Journal'!$C:$C,"<"&EDATE(B$3,1)) -> 350 | C19: =SUMIFS('Clean Journal'!$F:$F,'Clean Journal'!$E:$E,"Interest Expense",'Clean Journal'!$C:$C,">="&C$3,'Clean Journal'!$C:$C,"<"&EDATE(C$3,1)) -> 325 | D19: =SUMIFS('Clean Journal'!$F:$F,'Clean Journal'!$E:$E,"Interest Expense",'Clean Journal'!$C:$C,">="&D$3,'Clean Journal'!$C:$C,"<"&EDATE(D$3,1)) -> 300 | E19: ='PP&E & Debt'!E19 -> 275 | F19: ='PP&E & Debt'!F19 -> 250 | G19: ='PP&E & Debt'!G19 -> 225 | H19: ='PP&E & Debt'!H19 -> 200 | I19: ='PP&E & Debt'!I19 -> 175 | J19: ='PP&E & Debt'!J19 -> 150 | K19: ='PP&E & Debt'!K19 -> 125 | L19: ='PP&E & Debt'!L19 -> 100 | M19: ='PP&E & Debt'!M19 -> 75
A20: Profit before tax | B20: =B18-B19 -> 436.67 | C20: =C18-C19 -> 2861.67 | D20: =D18-D19 -> 5946.67 | E20: =E18-E19 -> 8934.07 | F20: =F18-F19 -> 12266.462 | G20: =G18-G19 -> 15863.445 | H20: =H18-H19 -> 16024.534 | I20: =I18-I19 -> 19081.177 | ... M20: =M18-M19 -> 27015.677
A21: Income tax expense | B21: =SUMIFS('Clean Journal'!$F:$F,'Clean Journal'!$E:$E,"Income Tax Expense",'Clean Journal'!$C:$C,">="&B$3,'Clean Journal'!$C:$C,"<"&EDATE(B$3,1)) -> 117.9 | C21: =SUMIFS('Clean Journal'!$F:$F,'Clean Journal'!$E:$E,"Income Tax Expense",'Clean Journal'!$C:$C,">="&C$3,'Clean Journal'!$C:$C,"<"&EDATE(C$3,1)) -> 772.65 | D21: =SUMIFS('Clean Journal'!$F:$F,'Clean Journal'!$E:$E,"Income Tax Expense",'Clean Journal'!$C:$C,">="&D$3,'Clean Journal'!$C:$C,"<"&EDATE(D$3,1)) -> 1605.6 | E21: =MAX(0,E20*Assumptions!B19) -> 2412.1989 | F21: =MAX(0,F20*Assumptions!C19) -> 3311.9447 | G21: =MAX(0,G20*Assumptions!D19) -> 4283.1302 | H21: =MAX(0,H20*Assumptions!E19) -> 4326.6242 | I21: =MAX(0,I20*Assumptions!F19) -> 5151.9179 | J21: =MAX(0,J20*Assumptions!G19) -> 5876.3887 | K21: =MAX(0,K20*Assumptions!H19) -> 6335.3029 | L21: =MAX(0,L20*Assumptions!I19) -> 6807.7819 | M21: =MAX(0,M20*Assumptions!J19) -> 7294.2329
A22: Net income | B22: =B20-B21 -> 318.77 | C22: =C20-C21 -> 2089.02 | D22: =D20-D21 -> 4341.07 | E22: =E20-E21 -> 6521.8711 | F22: =F20-F21 -> 8954.5173 | G22: =G20-G21 -> 11580.315 | H22: =H20-H21 -> 11697.91 | I22: =I20-I21 -> 13929.259 | ... M22: =M20-M21 -> 19721.444

Sheet Balance Sheet
A1: Integrated Balance Sheet
B3: 46023 | C3: 46054 | D3: 46082 | E3: 46113 | F3: 46143 | G3: 46174 | H3: 46204 | I3: 46235 | J3: 46266 | K3: 46296 | L3: 46327 | M3: 46357
A4: ASSETS
A5: Cash | B5: ='Cash Flow'!B23 -> 52332.1 | C5: ='Cash Flow'!C23 -> 52534.45 | D5: ='Cash Flow'!D23 -> 51928.85 | E5: ='Cash Flow'!E23 -> 55209.651 | F5: ='Cash Flow'!F23 -> 64932.634 | G5: ='Cash Flow'!G23 -> 72089.538 | H5: ='Cash Flow'!H23 -> 63084.978 | I5: ='Cash Flow'!I23 -> 73684.977 | ... M5: ='Cash Flow'!M23 -> 133923.03
A6: Accounts receivable | B6: =SUMIFS(OpeningTB!$C:$C,OpeningTB!$B:$B,"Accounts Receivable")+SUMIFS('Clean Journal'!$F:$F,'Clean Journal'!$E:$E,"Accounts Receivable",'Clean Journal'!$C:$C,"<"&EDATE(B$3,1))-SUMIFS('Clean Journal'!$G:$G,'Clean Journal'!$E:$E,"Accounts Receivable",'Clean Journal'!$C:$C,"<"&EDATE(B$3,1)) -> 21000 | C6: =SUMIFS(OpeningTB!$C:$C,OpeningTB!$B:$B,"Accounts Receivable")+SUMIFS('Clean Journal'!$F:$F,'Clean Journal'!$E:$E,"Accounts Receivable",'Clean Journal'!$C:$C,"<"&EDATE(C$3,1))-SUMIFS('Clean Journal'!$G:$G,'Clean Journal'!$E:$E,"Accounts Receivable",'Clean Journal'!$C:$C,"<"&EDATE(C$3,1)) -> 22000 | D6: =SUMIFS(OpeningTB!$C:$C,OpeningTB!$B:$B,"Accounts Receivable")+SUMIFS('Clean Journal'!$F:$F,'Clean Journal'!$E:$E,"Accounts Receivable",'Clean Journal'!$C:$C,"<"&EDATE(D$3,1))-SUMIFS('Clean Journal'!$G:$G,'Clean Journal'!$E:$E,"Accounts Receivable",'Clean Journal'!$C:$C,"<"&EDATE(D$3,1)) -> 26000 | E6: ='Working Capital'!E12 -> 28512 | F6: ='Working Capital'!F12 -> 30792.96 | G6: ='Working Capital'!G12 -> 33256.397 | H6: ='Working Capital'!H12 -> 34919.217 | I6: ='Working Capital'!I12 -> 36665.177 | J6: ='Working Capital'!J12 -> 38498.436 | K6: ='Working Capital'!K12 -> 39653.389 | L6: ='Working Capital'!L12 -> 40842.991 | M6: ='Working Capital'!M12 -> 42068.281
A7: Inventory | B7: =SUMIFS(OpeningTB!$C:$C,OpeningTB!$B:$B,"Inventory")+SUMIFS('Clean Journal'!$F:$F,'Clean Journal'!$E:$E,"Inventory",'Clean Journal'!$C:$C,"<"&EDATE(B$3,1))-SUMIFS('Clean Journal'!$G:$G,'Clean Journal'!$E:$E,"Inventory",'Clean Journal'!$C:$C,"<"&EDATE(B$3,1)) -> 44320 | C7: =SUMIFS(OpeningTB!$C:$C,OpeningTB!$B:$B,"Inventory")+SUMIFS('Clean Journal'!$F:$F,'Clean Journal'!$E:$E,"Inventory",'Clean Journal'!$C:$C,"<"&EDATE(C$3,1))-SUMIFS('Clean Journal'!$G:$G,'Clean Journal'!$E:$E,"Inventory",'Clean Journal'!$C:$C,"<"&EDATE(C$3,1)) -> 47540 | D7: =SUMIFS(OpeningTB!$C:$C,OpeningTB!$B:$B,"Inventory")+SUMIFS('Clean Journal'!$F:$F,'Clean Journal'!$E:$E,"Inventory",'Clean Journal'!$C:$C,"<"&EDATE(D$3,1))-SUMIFS('Clean Journal'!$G:$G,'Clean Journal'!$E:$E,"Inventory",'Clean Journal'!$C:$C,"<"&EDATE(D$3,1)) -> 49820 | E7: ='Working Capital'!E16 -> 48498.912 | F7: ='Working Capital'!F16 -> 52378.825 | G7: ='Working Capital'!G16 -> 54997.766 | H7: ='Working Capital'!H16 -> 57747.655 | I7: ='Working Capital'!I16 -> 60635.037 | J7: ='Working Capital'!J16 -> 62454.088 | K7: ='Working Capital'!K16 -> 64327.711 | L7: ='Working Capital'!L16 -> 66257.542 | M7: ='Working Capital'!M16 -> 66257.542
A8: Equipment, gross | B8: =SUMIFS(OpeningTB!$C:$C,OpeningTB!$B:$B,"Equipment")+SUMIFS('Clean Journal'!$F:$F,'Clean Journal'!$E:$E,"Equipment",'Clean Journal'!$C:$C,"<"&EDATE(B$3,1))-SUMIFS('Clean Journal'!$G:$G,'Clean Journal'!$E:$E,"Equipment",'Clean Journal'!$C:$C,"<"&EDATE(B$3,1)) -> 48000 | C8: =SUMIFS(OpeningTB!$C:$C,OpeningTB!$B:$B,"Equipment")+SUMIFS('Clean Journal'!$F:$F,'Clean Journal'!$E:$E,"Equipment",'Clean Journal'!$C:$C,"<"&EDATE(C$3,1))-SUMIFS('Clean Journal'!$G:$G,'Clean Journal'!$E:$E,"Equipment",'Clean Journal'!$C:$C,"<"&EDATE(C$3,1)) -> 48000 | D8: =SUMIFS(OpeningTB!$C:$C,OpeningTB!$B:$B,"Equipment")+SUMIFS('Clean Journal'!$F:$F,'Clean Journal'!$E:$E,"Equipment",'Clean Journal'!$C:$C,"<"&EDATE(D$3,1))-SUMIFS('Clean Journal'!$G:$G,'Clean Journal'!$E:$E,"Equipment",'Clean Journal'!$C:$C,"<"&EDATE(D$3,1)) -> 48000 | E8: ='PP&E & Debt'!E7 -> 48000 | F8: ='PP&E & Debt'!F7 -> 48000 | G8: ='PP&E & Debt'!G7 -> 48000 | H8: ='PP&E & Debt'!H7 -> 66000 | I8: ='PP&E & Debt'!I7 -> 66000 | J8: ='PP&E & Debt'!J7 -> 66000 | K8: ='PP&E & Debt'!K7 -> 66000 | L8: ='PP&E & Debt'!L7 -> 66000 | M8: ='PP&E & Debt'!M7 -> 66000
A9: Accumulated depreciation | B9: =-SUMIFS(OpeningTB!$D:$D,OpeningTB!$B:$B,"Accumulated Depreciation")-SUMIFS('Clean Journal'!$G:$G,'Clean Journal'!$E:$E,"Accumulated Depreciation",'Clean Journal'!$C:$C,"<"&EDATE(B$3,1))+SUMIFS('Clean Journal'!$F:$F,'Clean Journal'!$E:$E,"Accumulated Depreciation",'Clean Journal'!$C:$C,"<"&EDATE(B$3,1)) -> -10333.33 | C9: =-SUMIFS(OpeningTB!$D:$D,OpeningTB!$B:$B,"Accumulated Depreciation")-SUMIFS('Clean Journal'!$G:$G,'Clean Journal'!$E:$E,"Accumulated Depreciation",'Clean Journal'!$C:$C,"<"&EDATE(C$3,1))+SUMIFS('Clean Journal'!$F:$F,'Clean Journal'!$E:$E,"Accumulated Depreciation",'Clean Journal'!$C:$C,"<"&EDATE(C$3,1)) -> -11666.66 | D9: =-SUMIFS(OpeningTB!$D:$D,OpeningTB!$B:$B,"Accumulated Depreciation")-SUMIFS('Clean Journal'!$G:$G,'Clean Journal'!$E:$E,"Accumulated Depreciation",'Clean Journal'!$C:$C,"<"&EDATE(D$3,1))+SUMIFS('Clean Journal'!$F:$F,'Clean Journal'!$E:$E,"Accumulated Depreciation",'Clean Journal'!$C:$C,"<"&EDATE(D$3,1)) -> -12999.99 | E9: =-'PP&E & Debt'!E10 -> -14333.32 | F9: =-'PP&E & Debt'!F10 -> -15666.65 | G9: =-'PP&E & Debt'!G10 -> -16999.98 | H9: =-'PP&E & Debt'!H10 -> -18833.31 | I9: =-'PP&E & Debt'!I10 -> -20166.64 | J9: =-'PP&E & Debt'!J10 -> -21499.97 | K9: =-'PP&E & Debt'!K10 -> -22833.3 | L9: =-'PP&E & Debt'!L10 -> -24166.63 | M9: =-'PP&E & Debt'!M10 -> -25499.96
A10: Net property, plant and equipment | B10: =B8+B9 -> 37666.67 | C10: =C8+C9 -> 36333.34 | D10: =D8+D9 -> 35000.01 | E10: =E8+E9 -> 33666.68 | F10: =F8+F9 -> 32333.35 | G10: =G8+G9 -> 31000.02 | H10: =H8+H9 -> 47166.69 | I10: =I8+I9 -> 45833.36 | ... M10: =M8+M9 -> 40500.04
A11: Total assets | B11: =SUM(B5:B7)+B10 -> 155318.77 | C11: =SUM(C5:C7)+C10 -> 158407.79 | D11: =SUM(D5:D7)+D10 -> 162748.86 | E11: =SUM(E5:E7)+E10 -> 165887.24 | F11: =SUM(F5:F7)+F10 -> 180437.77 | G11: =SUM(G5:G7)+G10 -> 191343.72 | H11: =SUM(H5:H7)+H10 -> 202918.54 | I11: =SUM(I5:I7)+I10 -> 216818.55 | ... M11: =SUM(M5:M7)+M10 -> 282748.89
A13: LIABILITIES
A14: Accounts payable | B14: =SUMIFS(OpeningTB!$D:$D,OpeningTB!$B:$B,"Accounts Payable")+SUMIFS('Clean Journal'!$G:$G,'Clean Journal'!$E:$E,"Accounts Payable",'Clean Journal'!$C:$C,"<"&EDATE(B$3,1))-SUMIFS('Clean Journal'!$F:$F,'Clean Journal'!$E:$E,"Accounts Payable",'Clean Journal'!$C:$C,"<"&EDATE(B$3,1)) -> 25000 | C14: =SUMIFS(OpeningTB!$D:$D,OpeningTB!$B:$B,"Accounts Payable")+SUMIFS('Clean Journal'!$G:$G,'Clean Journal'!$E:$E,"Accounts Payable",'Clean Journal'!$C:$C,"<"&EDATE(C$3,1))-SUMIFS('Clean Journal'!$F:$F,'Clean Journal'!$E:$E,"Accounts Payable",'Clean Journal'!$C:$C,"<"&EDATE(C$3,1)) -> 28000 | D14: =SUMIFS(OpeningTB!$D:$D,OpeningTB!$B:$B,"Accounts Payable")+SUMIFS('Clean Journal'!$G:$G,'Clean Journal'!$E:$E,"Accounts Payable",'Clean Journal'!$C:$C,"<"&EDATE(D$3,1))-SUMIFS('Clean Journal'!$F:$F,'Clean Journal'!$E:$E,"Accounts Payable",'Clean Journal'!$C:$C,"<"&EDATE(D$3,1)) -> 30000 | E14: ='Working Capital'!E20 -> 28616.512 | F14: ='Working Capital'!F20 -> 36212.521 | G14: ='Working Capital'!G20 -> 37538.158 | H14: ='Working Capital'!H20 -> 39415.066 | I14: ='Working Capital'!I20 -> 41385.819 | J14: ='Working Capital'!J20 -> 42242.409 | K14: ='Working Capital'!K20 -> 43509.682 | L14: ='Working Capital'!L20 -> 44814.972 | M14: ='Working Capital'!M20 -> 44171.695
A15: Business loan | B15: =SUMIFS(OpeningTB!$D:$D,OpeningTB!$B:$B,"Business Loan")+SUMIFS('Clean Journal'!$G:$G,'Clean Journal'!$E:$E,"Business Loan",'Clean Journal'!$C:$C,"<"&EDATE(B$3,1))-SUMIFS('Clean Journal'!$F:$F,'Clean Journal'!$E:$E,"Business Loan",'Clean Journal'!$C:$C,"<"&EDATE(B$3,1)) -> 26000 | C15: =SUMIFS(OpeningTB!$D:$D,OpeningTB!$B:$B,"Business Loan")+SUMIFS('Clean Journal'!$G:$G,'Clean Journal'!$E:$E,"Business Loan",'Clean Journal'!$C:$C,"<"&EDATE(C$3,1))-SUMIFS('Clean Journal'!$F:$F,'Clean Journal'!$E:$E,"Business Loan",'Clean Journal'!$C:$C,"<"&EDATE(C$3,1)) -> 24000 | D15: =SUMIFS(OpeningTB!$D:$D,OpeningTB!$B:$B,"Business Loan")+SUMIFS('Clean Journal'!$G:$G,'Clean Journal'!$E:$E,"Business Loan",'Clean Journal'!$C:$C,"<"&EDATE(D$3,1))-SUMIFS('Clean Journal'!$F:$F,'Clean Journal'!$E:$E,"Business Loan",'Clean Journal'!$C:$C,"<"&EDATE(D$3,1)) -> 22000 | E15: ='PP&E & Debt'!E17 -> 20000 | F15: ='PP&E & Debt'!F17 -> 18000 | G15: ='PP&E & Debt'!G17 -> 16000 | H15: ='PP&E & Debt'!H17 -> 14000 | I15: ='PP&E & Debt'!I17 -> 12000 | J15: ='PP&E & Debt'!J17 -> 10000 | K15: ='PP&E & Debt'!K17 -> 8000 | L15: ='PP&E & Debt'!L17 -> 6000 | M15: ='PP&E & Debt'!M17 -> 4000
A16: Total liabilities | B16: =SUM(B14:B15) -> 51000 | C16: =SUM(C14:C15) -> 52000 | D16: =SUM(D14:D15) -> 52000 | E16: =SUM(E14:E15) -> 48616.512 | F16: =SUM(F14:F15) -> 54212.521 | G16: =SUM(G14:G15) -> 53538.158 | H16: =SUM(H14:H15) -> 53415.066 | I16: =SUM(I14:I15) -> 53385.819 | ... M16: =SUM(M14:M15) -> 48171.695
A18: EQUITY
A19: Owner capital | B19: =SUMIFS(OpeningTB!$D:$D,OpeningTB!$B:$B,"Owner Capital")+SUMIFS('Clean Journal'!$G:$G,'Clean Journal'!$E:$E,"Owner Capital",'Clean Journal'!$C:$C,"<"&EDATE(B$3,1))-SUMIFS('Clean Journal'!$F:$F,'Clean Journal'!$E:$E,"Owner Capital",'Clean Journal'!$C:$C,"<"&EDATE(B$3,1)) -> 70000 | C19: =SUMIFS(OpeningTB!$D:$D,OpeningTB!$B:$B,"Owner Capital")+SUMIFS('Clean Journal'!$G:$G,'Clean Journal'!$E:$E,"Owner Capital",'Clean Journal'!$C:$C,"<"&EDATE(C$3,1))-SUMIFS('Clean Journal'!$F:$F,'Clean Journal'!$E:$E,"Owner Capital",'Clean Journal'!$C:$C,"<"&EDATE(C$3,1)) -> 70000 | D19: =SUMIFS(OpeningTB!$D:$D,OpeningTB!$B:$B,"Owner Capital")+SUMIFS('Clean Journal'!$G:$G,'Clean Journal'!$E:$E,"Owner Capital",'Clean Journal'!$C:$C,"<"&EDATE(D$3,1))-SUMIFS('Clean Journal'!$F:$F,'Clean Journal'!$E:$E,"Owner Capital",'Clean Journal'!$C:$C,"<"&EDATE(D$3,1)) -> 70000 | E19: =D19 -> 70000 | F19: =E19 -> 70000 | G19: =F19 -> 70000 | H19: =G19 -> 70000 | I19: =H19 -> 70000 | J19: =I19 -> 70000 | K19: =J19 -> 70000 | L19: =K19 -> 70000 | M19: =L19 -> 70000
A20: Retained earnings | B20: =SUMIFS(OpeningTB!$D:$D,OpeningTB!$B:$B,"Retained Earnings")+SUM('Income Statement'!$B$22:B22) -> 34318.77 | C20: =SUMIFS(OpeningTB!$D:$D,OpeningTB!$B:$B,"Retained Earnings")+SUM('Income Statement'!$B$22:C22) -> 36407.79 | D20: =SUMIFS(OpeningTB!$D:$D,OpeningTB!$B:$B,"Retained Earnings")+SUM('Income Statement'!$B$22:D22) -> 40748.86 | E20: =D20+'Income Statement'!E22 -> 47270.731 | F20: =E20+'Income Statement'!F22 -> 56225.248 | G20: =F20+'Income Statement'!G22 -> 67805.563 | H20: =G20+'Income Statement'!H22 -> 79503.473 | I20: =H20+'Income Statement'!I22 -> 93432.733 | J20: =I20+'Income Statement'!J22 -> 109320.75 | K20: =J20+'Income Statement'!K22 -> 126449.53 | L20: =K20+'Income Statement'!L22 -> 144855.75 | M20: =L20+'Income Statement'!M22 -> 164577.2
A21: Total equity | B21: =SUM(B19:B20) -> 104318.77 | C21: =SUM(C19:C20) -> 106407.79 | D21: =SUM(D19:D20) -> 110748.86 | E21: =SUM(E19:E20) -> 117270.73 | F21: =SUM(F19:F20) -> 126225.25 | G21: =SUM(G19:G20) -> 137805.56 | H21: =SUM(H19:H20) -> 149503.47 | I21: =SUM(I19:I20) -> 163432.73 | ... M21: =SUM(M19:M20) -> 234577.2
A22: Total liabilities and equity | B22: =B16+B21 -> 155318.77 | C22: =C16+C21 -> 158407.79 | D22: =D16+D21 -> 162748.86 | E22: =E16+E21 -> 165887.24 | F22: =F16+F21 -> 180437.77 | G22: =G16+G21 -> 191343.72 | H22: =H16+H21 -> 202918.54 | I22: =I16+I21 -> 216818.55 | ... M22: =M16+M21 -> 282748.89
A23: Balance check | B23: =B11-B22 -> 0 | C23: =C11-C22 -> 0 | D23: =D11-D22 -> 0 | E23: =E11-E22 -> 0 | F23: =F11-F22 -> 0 | G23: =G11-G22 -> 0 | H23: =H11-H22 -> 0 | I23: =I11-I22 -> 0 | ... M23: =M11-M22 -> 0

Sheet Cash Flow
A1: Integrated Cash Flow Statement
B3: 46023 | C3: 46054 | D3: 46082 | E3: 46113 | F3: 46143 | G3: 46174 | H3: 46204 | I3: 46235 | J3: 46266 | K3: 46296 | L3: 46327 | M3: 46357
A4: OPERATING ACTIVITIES
A5: Net income | B5: ='Income Statement'!B22 -> 318.77 | C5: ='Income Statement'!C22 -> 2089.02 | D5: ='Income Statement'!D22 -> 4341.07 | E5: ='Income Statement'!E22 -> 6521.8711 | F5: ='Income Statement'!F22 -> 8954.5173 | G5: ='Income Statement'!G22 -> 11580.315 | H5: ='Income Statement'!H22 -> 11697.91 | I5: ='Income Statement'!I22 -> 13929.259 | ... M5: ='Income Statement'!M22 -> 19721.444
A6: Add: depreciation | B6: ='Income Statement'!B14 -> 1333.33 | C6: ='Income Statement'!C14 -> 1333.33 | D6: ='Income Statement'!D14 -> 1333.33 | E6: ='Income Statement'!E14 -> 1333.33 | F6: ='Income Statement'!F14 -> 1333.33 | G6: ='Income Statement'!G14 -> 1333.33 | H6: ='Income Statement'!H14 -> 1833.33 | I6: ='Income Statement'!I14 -> 1333.33 | ... M6: ='Income Statement'!M14 -> 1333.33
A7: Change in accounts receivable | B7: =SUMIFS(OpeningTB!$C:$C,OpeningTB!$B:$B,"Accounts Receivable")-'Balance Sheet'!B6 -> -9000 | C7: ='Balance Sheet'!B6-'Balance Sheet'!C6 -> -1000 | D7: ='Balance Sheet'!C6-'Balance Sheet'!D6 -> -4000 | E7: ='Balance Sheet'!D6-'Balance Sheet'!E6 -> -2512 | F7: ='Balance Sheet'!E6-'Balance Sheet'!F6 -> -2280.96 | G7: ='Balance Sheet'!F6-'Balance Sheet'!G6 -> -2463.4368 | H7: ='Balance Sheet'!G6-'Balance Sheet'!H6 -> -1662.8198 | I7: ='Balance Sheet'!H6-'Balance Sheet'!I6 -> -1745.9608 | J7: ='Balance Sheet'!I6-'Balance Sheet'!J6 -> -1833.2589 | ... M7: ='Balance Sheet'!L6-'Balance Sheet'!M6 -> -1225.2897
A8: Change in inventory | B8: =SUMIFS(OpeningTB!$C:$C,OpeningTB!$B:$B,"Inventory")-'Balance Sheet'!B7 -> -2320 | C8: ='Balance Sheet'!B7-'Balance Sheet'!C7 -> -3220 | D8: ='Balance Sheet'!C7-'Balance Sheet'!D7 -> -2280 | E8: ='Balance Sheet'!D7-'Balance Sheet'!E7 -> 1321.088 | F8: ='Balance Sheet'!E7-'Balance Sheet'!F7 -> -3879.913 | G8: ='Balance Sheet'!F7-'Balance Sheet'!G7 -> -2618.9412 | H8: ='Balance Sheet'!G7-'Balance Sheet'!H7 -> -2749.8883 | I8: ='Balance Sheet'!H7-'Balance Sheet'!I7 -> -2887.3827 | J8: ='Balance Sheet'!I7-'Balance Sheet'!J7 -> -1819.0511 | ... M8: ='Balance Sheet'!L7-'Balance Sheet'!M7 -> 0
A9: Change in accounts payable | B9: ='Balance Sheet'!B14-SUMIFS(OpeningTB!$D:$D,OpeningTB!$B:$B,"Accounts Payable") -> 8000 | C9: ='Balance Sheet'!C14-'Balance Sheet'!B14 -> 3000 | D9: ='Balance Sheet'!D14-'Balance Sheet'!C14 -> 2000 | E9: ='Balance Sheet'!E14-'Balance Sheet'!D14 -> -1383.488 | F9: ='Balance Sheet'!F14-'Balance Sheet'!E14 -> 7596.009 | G9: ='Balance Sheet'!G14-'Balance Sheet'!F14 -> 1325.6369 | H9: ='Balance Sheet'!H14-'Balance Sheet'!G14 -> 1876.9079 | I9: ='Balance Sheet'!I14-'Balance Sheet'!H14 -> 1970.7533 | J9: ='Balance Sheet'!J14-'Balance Sheet'!I14 -> 856.59021 | ... M9: ='Balance Sheet'!M14-'Balance Sheet'!L14 -> -643.27711
A10: Net cash from operating activities | B10: =SUM(B5:B9) -> -1667.9 | C10: =SUM(C5:C9) -> 2202.35 | D10: =SUM(D5:D9) -> 1394.4 | E10: =SUM(E5:E9) -> 5280.8011 | F10: =SUM(F5:F9) -> 11722.983 | G10: =SUM(G5:G9) -> 9156.904 | H10: =SUM(H5:H9) -> 10995.44 | I10: =SUM(I5:I9) -> 12599.999 | ... M10: =SUM(M5:M9) -> 19186.208
A12: INVESTING ACTIVITIES
A13: Capital expenditure | B13: =-SUMIFS('Clean Journal'!$F:$F,'Clean Journal'!$E:$E,"Equipment",'Clean Journal'!$C:$C,">="&B$3,'Clean Journal'!$C:$C,"<"&EDATE(B$3,1)) -> -12000 | C13: =-SUMIFS('Clean Journal'!$F:$F,'Clean Journal'!$E:$E,"Equipment",'Clean Journal'!$C:$C,">="&C$3,'Clean Journal'!$C:$C,"<"&EDATE(C$3,1)) -> 0 | D13: =-SUMIFS('Clean Journal'!$F:$F,'Clean Journal'!$E:$E,"Equipment",'Clean Journal'!$C:$C,">="&D$3,'Clean Journal'!$C:$C,"<"&EDATE(D$3,1)) -> 0 | E13: =-'PP&E & Debt'!E6 -> 0 | F13: =-'PP&E & Debt'!F6 -> 0 | G13: =-'PP&E & Debt'!G6 -> 0 | H13: =-'PP&E & Debt'!H6 -> -18000 | I13: =-'PP&E & Debt'!I6 -> 0 | J13: =-'PP&E & Debt'!J6 -> 0 | K13: =-'PP&E & Debt'!K6 -> 0 | L13: =-'PP&E & Debt'!L6 -> 0 | M13: =-'PP&E & Debt'!M6 -> 0
A14: Net cash from investing activities | B14: =B13 -> -12000 | C14: =C13 -> 0 | D14: =D13 -> 0 | E14: =E13 -> 0 | F14: =F13 -> 0 | G14: =G13 -> 0 | H14: =H13 -> -18000 | I14: =I13 -> 0 | ... M14: =M13 -> 0
A16: FINANCING ACTIVITIES
A17: Change in business loan | B17: ='Balance Sheet'!B15-SUMIFS(OpeningTB!$D:$D,OpeningTB!$B:$B,"Business Loan") -> -2000 | C17: ='Balance Sheet'!C15-'Balance Sheet'!B15 -> -2000 | D17: ='Balance Sheet'!D15-'Balance Sheet'!C15 -> -2000 | E17: ='PP&E & Debt'!E15-'PP&E & Debt'!E16 -> -2000 | F17: ='PP&E & Debt'!F15-'PP&E & Debt'!F16 -> -2000 | G17: ='PP&E & Debt'!G15-'PP&E & Debt'!G16 -> -2000 | H17: ='PP&E & Debt'!H15-'PP&E & Debt'!H16 -> -2000 | I17: ='PP&E & Debt'!I15-'PP&E & Debt'!I16 -> -2000 | J17: ='PP&E & Debt'!J15-'PP&E & Debt'!J16 -> -2000 | K17: ='PP&E & Debt'!K15-'PP&E & Debt'!K16 -> -2000 | L17: ='PP&E & Debt'!L15-'PP&E & Debt'!L16 -> -2000 | M17: ='PP&E & Debt'!M15-'PP&E & Debt'!M16 -> -2000
A18: Change in owner capital | B18: ='Balance Sheet'!B19-SUMIFS(OpeningTB!$D:$D,OpeningTB!$B:$B,"Owner Capital") -> 0 | C18: ='Balance Sheet'!C19-'Balance Sheet'!B19 -> 0 | D18: ='Balance Sheet'!D19-'Balance Sheet'!C19 -> 0 | E18: =0 -> 0 | F18: =0 -> 0 | G18: =0 -> 0 | H18: =0 -> 0 | I18: =0 -> 0 | J18: =0 -> 0 | K18: =0 -> 0 | L18: =0 -> 0 | M18: =0 -> 0
A19: Net cash from financing activities | B19: =SUM(B17:B18) -> -2000 | C19: =SUM(C17:C18) -> -2000 | D19: =SUM(D17:D18) -> -2000 | E19: =SUM(E17:E18) -> -2000 | F19: =SUM(F17:F18) -> -2000 | G19: =SUM(G17:G18) -> -2000 | H19: =SUM(H17:H18) -> -2000 | I19: =SUM(I17:I18) -> -2000 | ... M19: =SUM(M17:M18) -> -2000
A21: Net change in cash | B21: =B10+B14+B19 -> -15667.9 | C21: =C10+C14+C19 -> 202.35 | D21: =D10+D14+D19 -> -605.6 | E21: =E10+E14+E19 -> 3280.8011 | F21: =F10+F14+F19 -> 9722.9833 | G21: =G10+G14+G19 -> 7156.904 | H21: =H10+H14+H19 -> -9004.5603 | I21: =I10+I14+I19 -> 10599.999 | ... M21: =M10+M14+M19 -> 17186.208
A22: Beginning cash | B22: =SUMIFS(OpeningTB!$C:$C,OpeningTB!$B:$B,"Bank") -> 68000 | C22: =B23 -> 52332.1 | D22: =C23 -> 52534.45 | E22: =D23 -> 51928.85 | F22: =E23 -> 55209.651 | G22: =F23 -> 64932.634 | H22: =G23 -> 72089.538 | I22: =H23 -> 63084.978 | J22: =I23 -> 73684.977 | ... M22: =L23 -> 116736.82
A23: Ending cash | B23: =B22+B21 -> 52332.1 | C23: =C22+C21 -> 52534.45 | D23: =D22+D21 -> 51928.85 | E23: =E22+E21 -> 55209.651 | F23: =F22+F21 -> 64932.634 | G23: =G22+G21 -> 72089.538 | H23: =H22+H21 -> 63084.978 | I23: =I22+I21 -> 73684.977 | ... M23: =M22+M21 -> 133923.03
A24: Ending cash per balance sheet | B24: ='Balance Sheet'!B5 -> 52332.1 | C24: ='Balance Sheet'!C5 -> 52534.45 | D24: ='Balance Sheet'!D5 -> 51928.85 | E24: ='Balance Sheet'!E5 -> 55209.651 | F24: ='Balance Sheet'!F5 -> 64932.634 | G24: ='Balance Sheet'!G5 -> 72089.538 | H24: ='Balance Sheet'!H5 -> 63084.978 | I24: ='Balance Sheet'!I5 -> 73684.977 | ... M24: ='Balance Sheet'!M5 -> 133923.03
A25: Cash check | B25: =B23-B24 -> 0 | C25: =C23-C24 -> 0 | D25: =D23-D24 -> 0 | E25: =E23-E24 -> 0 | F25: =F23-F24 -> 0 | G25: =G23-G24 -> 0 | H25: =H23-H24 -> 0 | I25: =I23-I24 -> 0 | ... M25: =M23-M24 -> 0

Sheet Working Capital
A1: Working Capital Schedule
B3: 46023 | C3: 46054 | D3: 46082 | E3: 46113 | F3: 46143 | G3: 46174 | H3: 46204 | I3: 46235 | J3: 46266 | K3: 46296 | L3: 46327 | M3: 46357
A4: Sales and collections
A5: Revenue | B5: ='Income Statement'!B5 -> 54000 | C5: ='Income Statement'!C5 -> 59000 | D5: ='Income Statement'!D5 -> 66000 | E5: ='Income Statement'!E5 -> 71280 | F5: ='Income Statement'!F5 -> 76982.4 | G5: ='Income Statement'!G5 -> 83140.992 | H5: ='Income Statement'!H5 -> 87298.042 | I5: ='Income Statement'!I5 -> 91662.944 | ... M5: ='Income Statement'!M5 -> 105170.7
A6: Cash sales mix | B6: =0 -> 0 | C6: =0 -> 0 | D6: =0 -> 0 | E6: =Assumptions!B5 -> 0.6 | F6: =Assumptions!C5 -> 0.6 | G6: =Assumptions!D5 -> 0.6 | H6: =Assumptions!E5 -> 0.6 | I6: =Assumptions!F5 -> 0.6 | J6: =Assumptions!G5 -> 0.6 | K6: =Assumptions!H5 -> 0.6 | L6: =Assumptions!I5 -> 0.6 | M6: =Assumptions!J5 -> 0.6
A7: Cash sales | B7: ='Cash Flow'!B5+'Cash Flow'!B7 -> -8681.23 | C7: ='Cash Flow'!C5+'Cash Flow'!C7 -> 1089.02 | D7: ='Cash Flow'!D5+'Cash Flow'!D7 -> 341.07 | E7: =E5*E6 -> 42768 | F7: =F5*F6 -> 46189.44 | G7: =G5*G6 -> 49884.595 | H7: =H5*H6 -> 52378.825 | I7: =I5*I6 -> 54997.766 | J7: =J5*J6 -> 57747.655 | K7: =K5*K6 -> 59480.084 | L7: =L5*L6 -> 61264.487 | M7: =M5*M6 -> 63102.421
A8: Credit sales mix | B8: =0 -> 0 | C8: =0 -> 0 | D8: =0 -> 0 | E8: =Assumptions!B6 -> 0.4 | F8: =Assumptions!C6 -> 0.4 | G8: =Assumptions!D6 -> 0.4 | H8: =Assumptions!E6 -> 0.4 | I8: =Assumptions!F6 -> 0.4 | J8: =Assumptions!G6 -> 0.4 | K8: =Assumptions!H6 -> 0.4 | L8: =Assumptions!I6 -> 0.4 | M8: =Assumptions!J6 -> 0.4
A9: Credit sales | B9: ='Balance Sheet'!B6 -> 21000 | C9: ='Balance Sheet'!C6 -> 22000 | D9: ='Balance Sheet'!D6 -> 26000 | E9: =E5*E8 -> 28512 | F9: =F5*F8 -> 30792.96 | G9: =G5*G8 -> 33256.397 | H9: =H5*H8 -> 34919.217 | I9: =I5*I8 -> 36665.177 | J9: =J5*J8 -> 38498.436 | K9: =K5*K8 -> 39653.389 | L9: =L5*L8 -> 40842.991 | M9: =M5*M8 -> 42068.281
A10: Opening accounts receivable | B10: =0 -> 0 | C10: =0 -> 0 | D10: =0 -> 0 | E10: ='Balance Sheet'!D6 -> 26000 | F10: =E12 -> 28512 | G10: =F12 -> 30792.96 | H10: =G12 -> 33256.397 | I10: =H12 -> 34919.217 | J10: =I12 -> 36665.177 | K10: =J12 -> 38498.436 | L10: =K12 -> 39653.389 | M10: =L12 -> 40842.991
A11: Cash collections | B11: ='Cash Flow'!B5+'Cash Flow'!B7 -> -8681.23 | C11: ='Cash Flow'!C5+'Cash Flow'!C7 -> 1089.02 | D11: ='Cash Flow'!D5+'Cash Flow'!D7 -> 341.07 | E11: =E7+E10 -> 68768 | F11: =F7+F10 -> 74701.44 | G11: =G7+G10 -> 80677.555 | H11: =H7+H10 -> 85635.222 | I11: =I7+I10 -> 89916.983 | J11: =J7+J10 -> 94412.832 | K11: =K7+K10 -> 97978.52 | L11: =L7+L10 -> 100917.88 | M11: =M7+M10 -> 103945.41
A12: Ending accounts receivable | B12: ='Balance Sheet'!B6 -> 21000 | C12: ='Balance Sheet'!C6 -> 22000 | D12: ='Balance Sheet'!D6 -> 26000 | E12: =E9 -> 28512 | F12: =F9 -> 30792.96 | G12: =G9 -> 33256.397 | H12: =H9 -> 34919.217 | I12: =I9 -> 36665.177 | J12: =J9 -> 38498.436 | K12: =K9 -> 39653.389 | L12: =L9 -> 40842.991 | M12: =M9 -> 42068.281
A13: Inventory and supplier schedule
A14: Cost of sales | B14: ='Income Statement'!B6 -> 22680 | C14: ='Income Statement'!C6 -> 24780 | D14: ='Income Statement'!D6 -> 27720 | E14: ='Income Statement'!E6 -> 29937.6 | F14: ='Income Statement'!F6 -> 32332.608 | G14: ='Income Statement'!G6 -> 34919.217 | H14: ='Income Statement'!H6 -> 36665.177 | I14: ='Income Statement'!I6 -> 38498.436 | ... M14: ='Income Statement'!M6 -> 44171.695
A15: Inventory cover (months) | B15: =0 -> 0 | C15: =0 -> 0 | D15: =0 -> 0 | E15: =Assumptions!B8 -> 1.5 | F15: =Assumptions!C8 -> 1.5 | G15: =Assumptions!D8 -> 1.5 | H15: =Assumptions!E8 -> 1.5 | I15: =Assumptions!F8 -> 1.5 | J15: =Assumptions!G8 -> 1.5 | K15: =Assumptions!H8 -> 1.5 | L15: =Assumptions!I8 -> 1.5 | M15: =Assumptions!J8 -> 1.5
A16: Ending inventory | B16: ='Balance Sheet'!B7 -> 44320 | C16: ='Balance Sheet'!C7 -> 47540 | D16: ='Balance Sheet'!D7 -> 49820 | E16: ='Income Statement'!F6*E15 -> 48498.912 | F16: ='Income Statement'!G6*F15 -> 52378.825 | G16: ='Income Statement'!H6*G15 -> 54997.766 | H16: ='Income Statement'!I6*H15 -> 57747.655 | I16: ='Income Statement'!J6*I15 -> 60635.037 | J16: ='Income Statement'!K6*J15 -> 62454.088 | K16: ='Income Statement'!L6*K15 -> 64327.711 | L16: ='Income Statement'!M6*L15 -> 66257.542 | M16: ='Income Statement'!M6*M15 -> 66257.542
A17: Opening inventory | B17: =0 -> 0 | C17: =0 -> 0 | D17: =0 -> 0 | E17: ='Balance Sheet'!D7 -> 49820 | F17: =E16 -> 48498.912 | G17: =F16 -> 52378.825 | H17: =G16 -> 54997.766 | I17: =H16 -> 57747.655 | J17: =I16 -> 60635.037 | K17: =J16 -> 62454.088 | L17: =K16 -> 64327.711 | M17: =L16 -> 66257.542
A18: Inventory purchases | B18: =SUMIFS('Clean Journal'!$F:$F,'Clean Journal'!$E:$E,"Inventory",'Clean Journal'!$C:$C,">="&B$3,'Clean Journal'!$C:$C,"<"&EDATE(B$3,1)) -> 25000 | C18: =SUMIFS('Clean Journal'!$F:$F,'Clean Journal'!$E:$E,"Inventory",'Clean Journal'!$C:$C,">="&C$3,'Clean Journal'!$C:$C,"<"&EDATE(C$3,1)) -> 28000 | D18: =SUMIFS('Clean Journal'!$F:$F,'Clean Journal'!$E:$E,"Inventory",'Clean Journal'!$C:$C,">="&D$3,'Clean Journal'!$C:$C,"<"&EDATE(D$3,1)) -> 30000 | E18: =E14+E16-E17 -> 28616.512 | F18: =F14+F16-F17 -> 36212.521 | G18: =G14+G16-G17 -> 37538.158 | H18: =H14+H16-H17 -> 39415.066 | I18: =I14+I16-I17 -> 41385.819 | J18: =J14+J16-J17 -> 42242.409 | K18: =K14+K16-K17 -> 43509.682 | L18: =L14+L16-L17 -> 44814.972 | M18: =M14+M16-M17 -> 44171.695
A19: Opening accounts payable | B19: =0 -> 0 | C19: =0 -> 0 | D19: =0 -> 0 | E19: ='Balance Sheet'!D14 -> 30000 | F19: =E20 -> 28616.512 | G19: =F20 -> 36212.521 | H19: =G20 -> 37538.158 | I19: =H20 -> 39415.066 | J19: =I20 -> 41385.819 | K19: =J20 -> 42242.409 | L19: =K20 -> 43509.682 | M19: =L20 -> 44814.972
A20: Ending accounts payable | B20: ='Balance Sheet'!B14 -> 25000 | C20: ='Balance Sheet'!C14 -> 28000 | D20: ='Balance Sheet'!D14 -> 30000 | E20: =E18 -> 28616.512 | F20: =F18 -> 36212.521 | G20: =G18 -> 37538.158 | H20: =H18 -> 39415.066 | I20: =I18 -> 41385.819 | J20: =J18 -> 42242.409 | K20: =K18 -> 43509.682 | L20: =L18 -> 44814.972 | M20: =M18 -> 44171.695
A21: Supplier cash payments | B21: =0 -> 0 | C21: =0 -> 0 | D21: =0 -> 0 | E21: =E19+E18-E20 -> 30000 | F21: =F19+F18-F20 -> 28616.512 | G21: =G19+G18-G20 -> 36212.521 | H21: =H19+H18-H20 -> 37538.158 | I21: =I19+I18-I20 -> 39415.066 | J21: =J19+J18-J20 -> 41385.819 | K21: =K19+K18-K20 -> 42242.409 | L21: =L19+L18-L20 -> 43509.682 | M21: =M19+M18-M20 -> 44814.972

Sheet PP&E & Debt
A1: PP&E and Debt Schedules
B3: 46023 | C3: 46054 | D3: 46082 | E3: 46113 | F3: 46143 | G3: 46174 | H3: 46204 | I3: 46235 | J3: 46266 | K3: 46296 | L3: 46327 | M3: 46357
A4: Property, plant and equipment
A5: Opening gross equipment | B5: =SUMIFS(OpeningTB!$C:$C,OpeningTB!$B:$B,"Equipment") -> 36000 | C5: =B7 -> 48000 | D5: =C7 -> 48000 | E5: =D7 -> 48000 | F5: =E7 -> 48000 | G5: =F7 -> 48000 | H5: =G7 -> 48000 | I5: =H7 -> 66000 | J5: =I7 -> 66000 | ... M5: =L7 -> 66000
A6: Capital expenditure | B6: =SUMIFS('Clean Journal'!$F:$F,'Clean Journal'!$E:$E,"Equipment",'Clean Journal'!$C:$C,">="&B$3,'Clean Journal'!$C:$C,"<"&EDATE(B$3,1)) -> 12000 | C6: =SUMIFS('Clean Journal'!$F:$F,'Clean Journal'!$E:$E,"Equipment",'Clean Journal'!$C:$C,">="&C$3,'Clean Journal'!$C:$C,"<"&EDATE(C$3,1)) -> 0 | D6: =SUMIFS('Clean Journal'!$F:$F,'Clean Journal'!$E:$E,"Equipment",'Clean Journal'!$C:$C,">="&D$3,'Clean Journal'!$C:$C,"<"&EDATE(D$3,1)) -> 0 | E6: =Assumptions!B14 -> 0 | F6: =Assumptions!C14 -> 0 | G6: =Assumptions!D14 -> 0 | H6: =Assumptions!E14 -> 18000 | I6: =Assumptions!F14 -> 0 | J6: =Assumptions!G14 -> 0 | K6: =Assumptions!H14 -> 0 | L6: =Assumptions!I14 -> 0 | M6: =Assumptions!J14 -> 0
A7: Closing gross equipment | B7: =B5+B6-SUMIFS('Clean Journal'!$G:$G,'Clean Journal'!$E:$E,"Equipment",'Clean Journal'!$C:$C,">="&B$3,'Clean Journal'!$C:$C,"<"&EDATE(B$3,1)) -> 48000 | C7: =C5+C6-SUMIFS('Clean Journal'!$G:$G,'Clean Journal'!$E:$E,"Equipment",'Clean Journal'!$C:$C,">="&C$3,'Clean Journal'!$C:$C,"<"&EDATE(C$3,1)) -> 48000 | D7: =D5+D6-SUMIFS('Clean Journal'!$G:$G,'Clean Journal'!$E:$E,"Equipment",'Clean Journal'!$C:$C,">="&D$3,'Clean Journal'!$C:$C,"<"&EDATE(D$3,1)) -> 48000 | E7: =E5+E6 -> 48000 | F7: =F5+F6 -> 48000 | G7: =G5+G6 -> 48000 | H7: =H5+H6 -> 66000 | I7: =I5+I6 -> 66000 | J7: =J5+J6 -> 66000 | K7: =K5+K6 -> 66000 | L7: =L5+L6 -> 66000 | M7: =M5+M6 -> 66000
A8: Opening accumulated depreciation | B8: =SUMIFS(OpeningTB!$D:$D,OpeningTB!$B:$B,"Accumulated Depreciation") -> 9000 | C8: =B10 -> 10333.33 | D8: =C10 -> 11666.66 | E8: =D10 -> 12999.99 | F8: =E10 -> 14333.32 | G8: =F10 -> 15666.65 | H8: =G10 -> 16999.98 | I8: =H10 -> 18833.31 | J8: =I10 -> 20166.64 | ... M8: =L10 -> 24166.63
A9: Depreciation expense | B9: =SUMIFS('Clean Journal'!$F:$F,'Clean Journal'!$E:$E,"Depreciation Expense",'Clean Journal'!$C:$C,">="&B$3,'Clean Journal'!$C:$C,"<"&EDATE(B$3,1)) -> 1333.33 | C9: =SUMIFS('Clean Journal'!$F:$F,'Clean Journal'!$E:$E,"Depreciation Expense",'Clean Journal'!$C:$C,">="&C$3,'Clean Journal'!$C:$C,"<"&EDATE(C$3,1)) -> 1333.33 | D9: =SUMIFS('Clean Journal'!$F:$F,'Clean Journal'!$E:$E,"Depreciation Expense",'Clean Journal'!$C:$C,">="&D$3,'Clean Journal'!$C:$C,"<"&EDATE(D$3,1)) -> 1333.33 | E9: =Assumptions!B16+IF(E6>0,E6/Assumptions!B15,0) -> 1333.33 | F9: =Assumptions!C16+IF(F6>0,F6/Assumptions!C15,0) -> 1333.33 | G9: =Assumptions!D16+IF(G6>0,G6/Assumptions!D15,0) -> 1333.33 | H9: =Assumptions!E16+IF(H6>0,H6/Assumptions!E15,0) -> 1833.33 | I9: =Assumptions!F16+IF(I6>0,I6/Assumptions!F15,0) -> 1333.33 | J9: =Assumptions!G16+IF(J6>0,J6/Assumptions!G15,0) -> 1333.33 | K9: =Assumptions!H16+IF(K6>0,K6/Assumptions!H15,0) -> 1333.33 | L9: =Assumptions!I16+IF(L6>0,L6/Assumptions!I15,0) -> 1333.33 | M9: =Assumptions!J16+IF(M6>0,M6/Assumptions!J15,0) -> 1333.33
A10: Closing accumulated depreciation | B10: =B8+B9 -> 10333.33 | C10: =C8+C9 -> 11666.66 | D10: =D8+D9 -> 12999.99 | E10: =E8+E9 -> 14333.32 | F10: =F8+F9 -> 15666.65 | G10: =G8+G9 -> 16999.98 | H10: =H8+H9 -> 18833.31 | I10: =I8+I9 -> 20166.64 | ... M10: =M8+M9 -> 25499.96
A11: Net PP&E | B11: =B7-B10 -> 37666.67 | C11: =C7-C10 -> 36333.34 | D11: =D7-D10 -> 35000.01 | E11: =E7-E10 -> 33666.68 | F11: =F7-F10 -> 32333.35 | G11: =G7-G10 -> 31000.02 | H11: =H7-H10 -> 47166.69 | I11: =I7-I10 -> 45833.36 | ... M11: =M7-M10 -> 40500.04
A13: Business loan and interest
A14: Opening loan balance | B14: =SUMIFS(OpeningTB!$D:$D,OpeningTB!$B:$B,"Business Loan") -> 28000 | C14: =B17 -> 26000 | D14: =C17 -> 24000 | E14: =D17 -> 22000 | F14: =E17 -> 20000 | G14: =F17 -> 18000 | H14: =G17 -> 16000 | I14: =H17 -> 14000 | J14: =I17 -> 12000 | ... M14: =L17 -> 6000
A15: New borrowing | B15: =0 -> 0 | C15: =0 -> 0 | D15: =0 -> 0 | E15: =0 -> 0 | F15: =0 -> 0 | G15: =0 -> 0 | H15: =0 -> 0 | I15: =0 -> 0 | ... M15: =0 -> 0
A16: Principal repayment | B16: =SUMIFS('Clean Journal'!$F:$F,'Clean Journal'!$E:$E,"Business Loan",'Clean Journal'!$C:$C,">="&B$3,'Clean Journal'!$C:$C,"<"&EDATE(B$3,1)) -> 2000 | C16: =SUMIFS('Clean Journal'!$F:$F,'Clean Journal'!$E:$E,"Business Loan",'Clean Journal'!$C:$C,">="&C$3,'Clean Journal'!$C:$C,"<"&EDATE(C$3,1)) -> 2000 | D16: =SUMIFS('Clean Journal'!$F:$F,'Clean Journal'!$E:$E,"Business Loan",'Clean Journal'!$C:$C,">="&D$3,'Clean Journal'!$C:$C,"<"&EDATE(D$3,1)) -> 2000 | E16: =MIN(E14,Assumptions!B18) -> 2000 | F16: =MIN(F14,Assumptions!C18) -> 2000 | G16: =MIN(G14,Assumptions!D18) -> 2000 | H16: =MIN(H14,Assumptions!E18) -> 2000 | I16: =MIN(I14,Assumptions!F18) -> 2000 | J16: =MIN(J14,Assumptions!G18) -> 2000 | K16: =MIN(K14,Assumptions!H18) -> 2000 | L16: =MIN(L14,Assumptions!I18) -> 2000 | M16: =MIN(M14,Assumptions!J18) -> 2000
